Workbook

Sheet This video (v5)
A1: Tornado video v5 — every visual on screen
A2: Video: docs/weather/renders/tornado_intelligence_phase3_v5.mp4 · 546.2 s (9:06) · your recorded voiceover · no weather CSV. One row per drawn element (each tornado track line, each label chip, each camera move). Counts below are formulas over the table.
A4: By family | E4: By visual type | I4: Map graphics by colour
A5: Family | B5: Count | C5: Total on-screen (s) | E5: Visual | F5: Count | G5: Added by | I5: Colour | J5: Hex | K5: Track lines | L5: Label chips | M5: Warning shapes | N5: All visuals
A6: Map data graphic | B6: =COUNTIF($D$41:$D$205,A6) | C6: =SUMIF($D$41:$D$205,A6,$K$41:$K$205) | E6: Camera start | F6: =COUNTIF($E$41:$E$205,E6) | G6: Your plan | I6: Yellow (EF0 tornado track) | J6: #FFE066 | K6: =COUNTIFS($H$41:$H$205,J6,$E$41:$E$205,"Tornado track line") | L6: =COUNTIFS($H$41:$H$205,J6,$E$41:$E$205,"Track label chip") | M6: =COUNTIFS($H$41:$H$205,J6,$D$41:$D$205,"Map data graphic",$E$41:$E$205,"Warning*") | N6: =COUNTIF($H$41:$H$205,J6)
A7: Map loop | B7: =COUNTIF($D$41:$D$205,A7) | C7: =SUMIF($D$41:$D$205,A7,$K$41:$K$205) | E7: Place label (dot + name) | F7: =COUNTIF($E$41:$E$205,E7) | G7: Engine (auto) | I7: Orange (EF1 tornado track) | J7: #FFA94D | K7: =COUNTIFS($H$41:$H$205,J7,$E$41:$E$205,"Tornado track line") | L7: =COUNTIFS($H$41:$H$205,J7,$E$41:$E$205,"Track label chip") | M7: =COUNTIFS($H$41:$H$205,J7,$D$41:$D$205,"Map data graphic",$E$41:$E$205,"Warning*") | N7: =COUNTIF($H$41:$H$205,J7)
A8: Map label | B8: =COUNTIF($D$41:$D$205,A8) | C8: =SUMIF($D$41:$D$205,A8,$K$41:$K$205) | E8: Headline lower-third | F8: =COUNTIF($E$41:$E$205,E8) | G8: Engine (auto) | I8: Red-orange (EF2 tornado track) | J8: #FF6B3D | K8: =COUNTIFS($H$41:$H$205,J8,$E$41:$E$205,"Tornado track line") | L8: =COUNTIFS($H$41:$H$205,J8,$E$41:$E$205,"Track label chip") | M8: =COUNTIFS($H$41:$H$205,J8,$D$41:$D$205,"Map data graphic",$E$41:$E$205,"Warning*") | N8: =COUNTIF($H$41:$H$205,J8)
A9: Legend / key | B9: =COUNTIF($D$41:$D$205,A9) | C9: =SUMIF($D$41:$D$205,A9,$K$41:$K$205) | E9: Vignette (dark edges) | F9: =COUNTIF($E$41:$E$205,E9) | G9: Teamplate style | I9: Red (tornado warning) | J9: #FF0000 | K9: =COUNTIFS($H$41:$H$205,J9,$E$41:$E$205,"Tornado track line") | L9: =COUNTIFS($H$41:$H$205,J9,$E$41:$E$205,"Track label chip") | M9: =COUNTIFS($H$41:$H$205,J9,$D$41:$D$205,"Map data graphic",$E$41:$E$205,"Warning*") | N9: =COUNTIF($H$41:$H$205,J9)
A10: Text card | B10: =COUNTIF($D$41:$D$205,A10) | C10: =SUMIF($D$41:$D$205,A10,$K$41:$K$205) | E10: Camera fly to place | F10: =COUNTIF($E$41:$E$205,E10) | G10: Your plan | I10: Orange (place label tag) | J10: #E8552B | K10: =COUNTIFS($H$41:$H$205,J10,$E$41:$E$205,"Tornado track line") | L10: =COUNTIFS($H$41:$H$205,J10,$E$41:$E$205,"Track label chip") | M10: =COUNTIFS($H$41:$H$205,J10,$D$41:$D$205,"Map data graphic",$E$41:$E$205,"Warning*") | N10: =COUNTIF($H$41:$H$205,J10)
A11: Source line | B11: =COUNTIF($D$41:$D$205,A11) | C11: =SUMIF($D$41:$D$205,A11,$K$41:$K$205) | E11: Camera slow push in | F11: =COUNTIF($E$41:$E$205,E11) | G11: Your plan | I11: Red (title highlight / headline) | J11: #D3122B | K11: =COUNTIFS($H$41:$H$205,J11,$E$41:$E$205,"Tornado track line") | L11: =COUNTIFS($H$41:$H$205,J11,$E$41:$E$205,"Track label chip") | M11: =COUNTIFS($H$41:$H$205,J11,$D$41:$D$205,"Map data graphic",$E$41:$E$205,"Warning*") | N11: =COUNTIF($H$41:$H$205,J11)
A12: Footage | B12: =COUNTIF($D$41:$D$205,A12) | C12: =SUMIF($D$41:$D$205,A12,$K$41:$K$205) | E12: Camera ease back out | F12: =COUNTIF($E$41:$E$205,E12) | G12: Your plan | I12: White (source lines) | J12: #FFFFFF | K12: =COUNTIFS($H$41:$H$205,J12,$E$41:$E$205,"Tornado track line") | L12: =COUNTIFS($H$41:$H$205,J12,$E$41:$E$205,"Track label chip") | M12: =COUNTIFS($H$41:$H$205,J12,$D$41:$D$205,"Map data graphic",$E$41:$E$205,"Warning*") | N12: =COUNTIF($H$41:$H$205,J12)
A13: Transition / effect | B13: =COUNTIF($D$41:$D$205,A13) | C13: =SUMIF($D$41:$D$205,A13,$K$41:$K$205) | E13: Stock video clip | F13: =COUNTIF($E$41:$E$205,E13) | G13: Your plan / Teamplate cutaway | I13: Black (place tag (top)) | J13: #111111 | K13: =COUNTIFS($H$41:$H$205,J13,$E$41:$E$205,"Tornado track line") | L13: =COUNTIFS($H$41:$H$205,J13,$E$41:$E$205,"Track label chip") | M13: =COUNTIFS($H$41:$H$205,J13,$D$41:$D$205,"Map data graphic",$E$41:$E$205,"Warning*") | N13: =COUNTIF($H$41:$H$205,J13)
A14: Camera move | B14: =COUNTIF($D$41:$D$205,A14) | C14: =SUMIF($D$41:$D$205,A14,$K$41:$K$205) | E14: Dip to dark (transition) | F14: =COUNTIF($E$41:$E$205,E14) | G14: Teamplate style | I14: Total | K14: =SUM(K6:K13) | L14: =SUM(L6:L13) | M14: =SUM(M6:M13) | N14: =SUM(N6:N13)
A15: Total | B15: =SUM(B6:B14) | C15: =SUM(C6:C14) | E15: Keyword title card | F15: =COUNTIF($E$41:$E$205,E15) | G15: Your plan (hud_title) in Teamplate style
A16: On-screen seconds overlap (several visuals at once), so the total is more than the video's length. | E16: Place tag (top) | F16: =COUNTIF($E$41:$E$205,E16) | G16: Teamplate style
E17: Legend panel | F17: =COUNTIF($E$41:$E$205,E17) | G17: Engine (auto) | I17: Tornado tracks drawn in v5, by the state they start in
E18: Tornado track line | F18: =COUNTIF($E$41:$E$205,E18) | G18: Engine (auto) | I18: State | J18: Track lines drawn | K18: Note
E19: Track label chip | F19: =COUNTIF($E$41:$E$205,E19) | G19: Engine (auto) | I19: SC | J19: =COUNTIFS($E$41:$E$205,"Tornado track line",$F$41:$F$205,"*starts in SC;*") | K19: the story's state: correct
A20: Key numbers | E20: Source line (bottom text) | F20: =COUNTIF($E$41:$E$205,E20) | G20: Engine (auto) | I20: GA | J20: =COUNTIFS($E$41:$E$205,"Tornado track line",$F$41:$F$205,"*starts in GA;*") | K20: outside the story: removed for the next render (fix made after v5)
A21: Video length (s) | B21: 546.23 | C21: ffprobe of the rendered file | E21: Radar colour scale | F21: =COUNTIF($E$41:$E$205,E21) | G21: Engine (auto) | I21: NC | J21: =COUNTIFS($E$41:$E$205,"Tornado track line",$F$41:$F$205,"*starts in NC;*") | K21: outside the story: removed for the next render (fix made after v5)
A22: Map beats / footage beats | B22: 32 / 20 | C22: the render plan (Teamplate cutaways included) | E22: Radar loop | F22: =COUNTIF($E$41:$E$205,E22) | G22: Engine (auto)
A23: Distinct graphic layers added by the engine | B23: =COUNTIFS($J$41:$J$205,"Engine (auto)") | C23: rows; a layer can be several rows | E23: Warning polygon (fill) | F23: =COUNTIF($E$41:$E$205,E23) | G23: Engine (auto)
A24: Camera moves added by the motion pass | B24: =COUNTIF($J$41:$J$205,"Motion pass (new)") | E24: Warning polygon (outline) | F24: =COUNTIF($E$41:$E$205,E24) | G24: Engine (auto)
A25: Footage clips | B25: =COUNTIF($D$41:$D$205,"Footage") | E25: Explainer card | F25: =COUNTIF($E$41:$E$205,E25) | G25: Engine (auto)
A26: Longest still stretch, v3 (s) | B26: 16.5 | C26: measured on the video: frames compared twice a second | E26: Total | F26: =SUM(F6:F25)
A27: Longest still stretch, v5 (s) | B27: 7 | C27: same measure
A28: Time in still stretches of 6 s or more, v3 (s) | B28: 73 | C28: same measure
A29: Time in still stretches of 6 s or more, v5 (s) | B29: 19.5 | C29: same measure
A39: Every visual, in time order
A40: Start (s) | B40: End (s) | C40: Beat | D40: Family | E40: Visual | F40: What it shows | G40: Colour | H40: Hex | I40: Data source | J40: Added by | K40: On screen (s) | L40: Starts at (m:ss)
A41: 0 | B41: 0 | C41: b1 | D41: Camera move | E41: Camera start | F41: South Carolina | G41: — | I41: — | J41: Your plan | K41: =B41-A41 | L41: 0:00.0
A42: 0 | B42: 9.84 | C42: b1 | D42: Map label | E42: Place label (dot + name) | F42: NEWBERRY COUNTY | G42: Orange tag | H42: #E8552B | I42: US county outlines (bundled) | J42: Engine (auto) | K42: =B42-A42 | L42: 0:00.0
A43: 0 | B43: 7 | C43: b1 | D43: Text card | E43: Headline lower-third | F43: TORNADO / NEWBERRY COUNTY, SOUTH CAROLINA / SUNDAY, OCTOBER 11, 2026 | G43: Red kicker, white title | H43: #D3122B | I43: — | J43: Engine (auto) | K43: =B43-A43 | L43: 0:00.0
A44: 0 | B44: 546.25 | C44: b1 | D44: Transition / effect | E44: Vignette (dark edges) | F44: whole video | G44: Black (edges) | H44: #000000 | I44: — | J44: Teamplate style | K44: =B44-A44 | L44: 0:00.0
A45: 1.4 | B45: 3.6 | C45: b1 | D45: Camera move | E45: Camera fly to place | F45: South Carolina | G45: — | I45: — | J45: Your plan | K45: =B45-A45 | L45: 0:01.4
A46: 3.9 | B46: 9.54 | C46: b1 | D46: Camera move | E46: Camera slow push in | F46: same place | G46: — | I46: — | J46: Your plan | K46: =B46-A46 | L46: 0:03.9
A47: 10.14 | B47: 18.26 | C47: b2 | D47: Camera move | E47: Camera ease back out | F47: same place | G47: — | I47: — | J47: Your plan | K47: =B47-A47 | L47: 0:10.1
A48: 18.56 | B48: 23.06 | C48: b2 | D48: Footage | E48: Stock video clip | F48: 001.mp4 | G48: Full colour (video) | I48: Pexels stock video | J48: Your plan / Teamplate cutaway | K48: =B48-A48 | L48: 0:18.6
A49: 23.36 | B49: 33.36 | C49: b3 | D49: Camera move | E49: Camera slow push in | F49: same place | G49: — | I49: — | J49: Your plan | K49: =B49-A49 | L49: 0:23.4
A50: 27.26 | B50: 36.48 | C50: b3 | D50: Map label | E50: Place label (dot + name) | F50: NEWBERRY COUNTY | G50: Orange tag | H50: #E8552B | I50: US county outlines (bundled) | J50: Engine (auto) | K50: =B50-A50 | L50: 0:27.3
...

Sheet All visuals
A1: Every visual Weather can put on screen
A2: Data layers live in weather/layers (drawn by weather-engine plugins); the engine (weather/intel) adds them by itself when the narration discusses them and the data exists. 'Used in v5' counts rows of the first sheet.
A4: Visual | B4: Family | C4: Layer / type | D4: What it shows | E4: Data source | F4: Colours | G4: The engine adds it when… | H4: Event types | I4: Used in v5 (rows)
A5: Tornado track line | B5: Map data graphic | C5: tornado_tracks | D5: each NWS-surveyed tornado path, drawn on the map | E5: NWS Damage Assessment Toolkit (preliminary) | F5: Yellow EF0 · Orange EF1 · Red-orange EF2 · Red EF3 · Magenta EF4 · Purple EF5 | G5: a beat describes the tornado's path/width (tornado, severe); again where the narration returns to it | H5: tornado, severe | I5: =COUNTIF('This video (v5)'!$E$41:$E$205,"Tornado track line")
A6: Track label chip | B6: Map data graphic | C6: tornado_tracks / storm_track | D6: EF · wind · length · width (survey) or CAT · MPH · time (hurricane) | E6: NWS DAT / NHC | F6: chip in the track's colour | G6: with the track it labels | H6: tornado, hurricane | I6: =COUNTIF('This video (v5)'!$E$41:$E$205,"Track label chip")
A7: Radar loop | B7: Map loop | C7: radar | D7: NEXRAD reflectivity frames with a clock | E7: NOAA/NWS NEXRAD via IEM | F7: blue-green-yellow-red-purple dBZ scale | G7: a beat talks about radar/warnings/the storm moving; window fitted to the warning | H7: tornado, severe, hurricane, flood | I7: =COUNTIF('This video (v5)'!$E$41:$E$205,"Radar loop")
A8: Warning polygon | B8: Map data graphic | C8: warnings_archive | D8: each NWS warning area from its issue time | E8: NWS warnings via IEM archive | F8: Red tornado · Yellow severe t-storm · Green flash flood · Orange extreme wind | G8: with the radar loop | H8: tornado, severe, hurricane, flood | I8: =COUNTIF('This video (v5)'!$E$41:$E$205,"Warning polygon*")
A9: Storm reports map | B9: Map data graphic | C9: storm_reports | D9: SPC tornado / wind / hail reports popping in, with a count | E9: SPC (preliminary) | F9: Red tornado · Blue wind · Green hail | G9: a beat discusses reports and no NWS survey exists | H9: tornado, severe | I9: =COUNTIF('This video (v5)'!$E$41:$E$205,"Storm reports map")
A10: Counter | B10: Panel / chart | C10: counter | D10: a number counting up (reports, warnings issued) | E10: SPC / IEM | F10: dark panel, yellow bar | G10: the narration states a count | H10: severe, hurricane | I10: =COUNTIF('This video (v5)'!$E$41:$E$205,"Counter")
A11: SPC outlook | B11: Map data graphic | C11: spc_outlook | D11: categorical severe-weather risk areas | E11: NOAA Storm Prediction Center | F11: Green marginal → Yellow slight → Orange enhanced → Red moderate → Magenta high | G11: the narration discusses the outlook | H11: tornado, severe | I11: =COUNTIF('This video (v5)'!$E$41:$E$205,"SPC outlook")
A12: Rain outlook (ERO) | B12: Map data graphic | C12: wpc_ero | D12: risk of excessive rainfall areas | E12: NOAA Weather Prediction Center | F12: Green / Yellow / Red / Magenta | G12: the narration discusses the rain outlook | H12: hurricane, flood | I12: =COUNTIF('This video (v5)'!$E$41:$E$205,"Rain outlook (ERO)")
A13: Hurricane cone | B13: Map data graphic | C13: storm_cone | D13: 5-day cone + coastal hurricane/TS watches and warnings | E13: NHC advisory archive | F13: White cone · Red/Pink/Blue/Yellow coast lines | G13: a beat mentions the cone/advisory (advisory chosen by the time said) | H13: hurricane | I13: =COUNTIF('This video (v5)'!$E$41:$E$205,"Hurricane cone")
A14: Hurricane track | B14: Map data graphic | C14: storm_track | D14: best track coloured by strength, or forecast track with points | E14: NHC best track / advisory | F14: Blue TD · Cyan TS · Yellow→Red Cat 1–5 | G14: a beat describes the path or strength | H14: hurricane, flood | I14: =COUNTIF('This video (v5)'!$E$41:$E$205,"Hurricane track")
A15: Storm statistics card | B15: Panel / chart | C15: storm_stats | D15: peak strength, lowest pressure, landfall | E15: NHC HURDAT2 (final) / working best track | F15: dark panel, red bar, yellow labels | G15: a beat discusses the storm's strength | H15: hurricane | I15: =COUNTIF('This video (v5)'!$E$41:$E$205,"Storm statistics card")
A16: Satellite loop | B16: Map loop | C16: satellite_loop | D16: daily true-colour or 10-minute GOES pictures | E16: NASA GIBS (VIIRS / GOES-East) | F16: natural colour | G16: a beat talks about the storm from space | H16: hurricane, flood | I16: =COUNTIF('This video (v5)'!$E$41:$E$205,"Satellite loop")
A17: Satellite still | B17: Map loop | C17: satellite | D17: one GOES GeoColor picture | E17: NASA GIBS | F17: natural colour | G17: user plans only | H17: any | I17: =COUNTIF('This video (v5)'!$E$41:$E$205,"Satellite still")
A18: Before / after | B18: Map loop | C18: before_after | D18: two satellite days cross-faded, labelled | E18: NASA GIBS | F18: natural or false colour (water dark blue) | G18: a beat compares before and after | H18: flood, hurricane | I18: =COUNTIF('This video (v5)'!$E$41:$E$205,"Before / after")
A19: Rain map | B19: Map data graphic | C19: rain_map | D19: multi-day radar-estimated rain with an inch legend | E19: NOAA MRMS via IEM (estimate) | F19: light green → blue → purple → magenta | G19: a beat talks about radar rainfall estimates | H19: flood, hurricane | I19: =COUNTIF('This video (v5)'!$E$41:$E$205,"Rain map")
A20: Rain totals (chip or bars) | B20: Panel / chart | C20: rain_total | D20: observed rain at gauges: a chip, or a bar chart | E20: NOAA RCC-ACIS | F20: cyan bars, white numbers | G20: a beat names gauges/places with totals | H20: flood, hurricane | I20: =COUNTIF('This video (v5)'!$E$41:$E$205,"Rain totals")
A21: Record badge | B21: Panel / chart | C21: record / temp_extreme | D21: 'wettest/hottest day on record', new vs old record | E21: NOAA RCC-ACIS | F21: blue rain · red heat · light blue cold | G21: a beat talks about a record | H21: flood, heat | I21: =COUNTIF('This video (v5)'!$E$41:$E$205,"Record badge")
A22: River crest + hydrograph | B22: Panel / chart | C22: river_crest | D22: a gauge's crest with flood stage, optional hydrograph | E22: USGS + NWS flood categories | F22: cyan chip; flood-stage lines | G22: a beat names a river and its crest | H22: flood | I22: =COUNTIF('This video (v5)'!$E$41:$E$205,"River crest")
A23: Event timeline | B23: Panel / chart | C23: event_timeline | D23: days with dated marks (landfall, wettest day, crest) | E23: NHC / ACIS / USGS | F23: dark panel, white/amber marks | G23: a beat says 'timeline' | H23: flood, hurricane | I23: =COUNTIF('This video (v5)'!$E$41:$E$205,"Event timeline")
A24: Explainer card | B24: Text card | C24: explainer | D24: fixed NWS definitions (watch vs warning) | E24: NWS (weather.gov) | F24: Yellow WATCH · Red WARNING | G24: a beat compares a watch and a warning | H24: tornado, severe | I24: =COUNTIF('This video (v5)'!$E$41:$E$205,"Explainer card")
A25: Headline lower-third | B25: Text card | C25: headline (tp_lower in Teamplate) | D25: kicker / title / date | E25: — (words only) | F25: Red news · Blue forecast · Amber post-event kicker | G25: the first map beat, when the plan has no title card there | H25: any | I25: =COUNTIF('This video (v5)'!$E$41:$E$205,"Headline lower-third")
A26: Place label | B26: Map label | C26: place_label (tp_place in Teamplate) | D26: a dot and a place name | E26: US county outlines / city list | F26: white dot, orange tag (Teamplate) | G26: a county/city with coordinates is named; long empty beats | H26: tornado, severe, flood | I26: =COUNTIF('This video (v5)'!$E$41:$E$205,"Place label (dot + name)")
A27: Landfall marker | B27: Map label | C27: place_label | D27: 'LANDFALL' at the best-track landfall point | E27: NHC HURDAT2 | F27: white dot + label | G27: a beat says it came ashore | H27: hurricane | I27: =COUNTIF('This video (v5)'!$E$41:$E$205,"Landfall marker")
A28: Legend panel | B28: Legend / key | C28: alert_legend | D28: colour key of the shapes on the map | E28: — | F28: dark panel with swatches | G28: with warnings, outlooks, tracks | H28: all | I28: =COUNTIF('This video (v5)'!$E$41:$E$205,"Legend panel")
A29: Radar colour scale | B29: Legend / key | C29: radar_legend | D29: LIGHT – HEAVY – HAIL bar | E29: — | F29: dBZ colours | G29: with the radar loop | H29: all | I29: =COUNTIF('This video (v5)'!$E$41:$E$205,"Radar colour scale")
A30: Source line | B30: Source line | C30: source_line | D30: names the data and its time on screen | E30: — | F30: white text | G30: every beat with data | H30: all | I30: =COUNTIF('This video (v5)'!$E$41:$E$205,"Source line (bottom text)")
A31: Forecast strip | B31: Panel / chart | C31: forecast_strip | D31: 5–7 day highs/lows/icons | E31: NWS API | F31: dark panel, white numbers | G31: a current forecast story | H31: forecast | I31: =COUNTIF('This video (v5)'!$E$41:$E$205,"Forecast strip")
A32: Temperature marker | B32: Map data graphic | C32: temp_marker | D32: a city's high/low/now on the map | E32: NWS API | F32: white chip | G32: forecast plans | H32: forecast | I32: =COUNTIF('This video (v5)'!$E$41:$E$205,"Temperature marker")
A33: Current conditions card | B33: Panel / chart | C33: now_card | D33: temperature now + sky | E33: NWS observations | F33: dark panel | G33: a current forecast story | H33: forecast | I33: =COUNTIF('This video (v5)'!$E$41:$E$205,"Current conditions card")
A34: Active alerts map | B34: Map data graphic | C34: alert_area | D34: today's NWS alert areas | E34: NWS API | F34: NWS alert colours | G34: a current story with alerts | H34: forecast | I34: =COUNTIF('This video (v5)'!$E$41:$E$205,"Active alerts map")
A35: Temperature trend | B35: Panel / chart | C35: temp_trend | D35: the week's highs and lows as a line chart | E35: NWS API | F35: red highs, blue lows | G35: forecast plans | H35: forecast | I35: =COUNTIF('This video (v5)'!$E$41:$E$205,"Temperature trend")
A36: Wind streaks | B36: Map data graphic | C36: wind_flow | D36: moving streaks the way the wind blows | E36: NWS forecast | F36: white streaks | G36: forecast plans | H36: forecast | I36: =COUNTIF('This video (v5)'!$E$41:$E$205,"Wind streaks")
A37: Footage credit chip | B37: Text card | C37: footage_credit | D37: credit of an approved event clip | E37: — | F37: dark chip | G37: approved event footage | H37: any | I37: =COUNTIF('This video (v5)'!$E$41:$E$205,"Footage credit chip")
A38: Keyword title card | B38: Text card | C38: tp_title (Teamplate) | D38: big words with a highlighted keyword | E38: your plan's title | F38: white, red highlight | G38: your plan's hud_title in Teamplate style | H38: any | I38: =COUNTIF('This video (v5)'!$E$41:$E$205,"Keyword title card")
A39: Place tag (top) | B39: Text card | C39: tp_tag (Teamplate) | D39: where the map is | E39: — | F39: black tag | G39: Teamplate style | H39: any | I39: =COUNTIF('This video (v5)'!$E$41:$E$205,"Place tag (top)")
A40: Big stat card | B40: Text card | C40: tp_stat (Teamplate) / stat (Hybrid) | D40: one number with a label | E40: your plan | F40: white / red | G40: your plan's stat layers | H40: any | I40: =COUNTIF('This video (v5)'!$E$41:$E$205,"Big stat card")
A41: Dip to dark | B41: Transition / effect | C41: tp_dip (Teamplate) | D41: short dark dip into a title card | E41: — | F41: black | G41: Teamplate style | H41: any | I41: =COUNTIF('This video (v5)'!$E$41:$E$205,"Dip to dark (transition)")
...
